Workbook

Sheet Introduction
A1: Lab-2 : ANP-D6305 -> Explain all the functions in Excel (Theory + Formula)
A2: Name: Asutosh Sunil Desai
A4: What is MS Excel?
A5: Microsoft Excel is a spreadsheet application used to store, organise, calculate and analyse data in rows and columns.
A6: A workbook contains sheets; a sheet is a grid of cells. Each cell has an address such as A1 (column A, row 1).
A8: Formula vs Function
A9: Formula: an expression written by the user that starts with '=' , e.g. =A1+B1*2
A10: Function: a built-in, predefined formula with a name and arguments, e.g. =SUM(A1:A10)
A11: Syntax of a function: =FUNCTION_NAME(argument1, argument2, ...)
A13: Types of Cell References
A14: Relative (A1) : changes when the formula is copied to another cell.
A15: Absolute ($A$1): stays fixed when copied (press F4 to add $).
... A28: Change any value in the 'Data' sheet and the results in the 'Functions' sheet update automatically.

Sheet Data
A1: Emp ID | B1: Name | C1: Department | D1: City | E1: Salary (Rs) | F1: Join Date | G1: Sales Q1 (Rs) | H1: Rating
A2: 101 | B2: rahul sharma | C2: Sales | D2: Mumbai | E2: 45000 | F2: 44270 | G2: 120000 | H2: 4
A3: 102 | B3: Priya Patil | C3: HR | D3: Pune | E3: 38000 | F3: 44013 | G3: 0 | H3: 5
A4: 103 | B4: Amit Joshi | C4: IT | D4: Mumbai | E4: 62000 | F4: 43475 | G4: 0 | H4: 3
A5: 104 | B5: Sneha Kulkarni | C5: Sales | D5: Thane | E5: 41000 | F5: 44885 | G5: 98000 | H5: 4
A6: 105 | B6: Rohan Mehta | C6: IT | D6: Pune | E6: 58000 | F6: 43225 | G6: 0 | H6: 5
A7: 106 | B7: Neha Desai | C7: Finance | D7: Mumbai | E7: 52000 | F7: 44451 | G7: 0 | H7: 4
A8: 107 | B8: Karan Shah | C8: Sales | D8: Virar | E8: 39000 | F8: 44958 | G8: 150000 | H8: 3
A9: 108 | B9: Pooja Naik | C9: Finance | D9: Thane | E9: 47000 | F9: 44183 | G9: 0 | H9: 2
A10: 109 | B10: Vikas More | C10: IT | D10: Virar | E10: 65000 | F10: 42972 | G10: 0 | H10: 4
A11: 110 | B11: Anjali Rao | C11: Sales | D11: Pune | E11: 43000 | F11: 44742 | G11: 87000 | H11: 5
A13: Horizontal table (used by HLOOKUP)
A14: Month | B14: Jan | C14: Feb | D14: Mar | E14: Apr | F14: May | G14: Jun
A15: Target (Rs) | B15: 50000 | C15: 55000 | D15: 60000 | E15: 58000 | F15: 62000 | G15: 70000
A17: Sample text (used by TRIM)
A18: Excel is powerful
A20: Loan inputs (used by PMT / FV / PV)
A21: Loan amount (Rs) | B21: 500000
A22: Annual interest rate | B22: 0.09
A23: Tenure (years) | B23: 5
A25: Blue text = sample input values (edit them to see the Functions sheet update).

Sheet Functions
A1: Lab-2 : Excel Functions - Theory + Formula (live examples use the 'Data' sheet)
A3: Sr No | B3: Category | C3: Function | D3: Theory (What it does) | E3: Syntax | F3: Formula Used | G3: Result
A4: 1 | B4: Math & Trig | C4: SUM | D4: Adds all the numbers in a range of cells. | E4: SUM(number1, [number2], ...) | F4: =SUM(Data!E2:E11) | G4: =SUM(Data!E2:E11) -> 490000
A5: 2 | B5: Math & Trig | C5: PRODUCT | D5: Multiplies all the numbers given as arguments. | E5: PRODUCT(number1, [number2], ...) | F5: =PRODUCT(5,4,2) | G5: =PRODUCT(5,4,2) -> 40
A6: 3 | B6: Math & Trig | C6: SUMIF | D6: Adds the cells that meet ONE condition. | E6: SUMIF(range, criteria, [sum_range]) | F6: =SUMIF(Data!C2:C11,"Sales",Data!E2:E11) | G6: =SUMIF(Data!C2:C11,"Sales",Data!E2:E11) -> 168000
A7: 4 | B7: Math & Trig | C7: SUMIFS | D7: Adds the cells that meet MULTIPLE conditions. | E7: SUMIFS(sum_range, criteria_range1, criteria1, ...) | F7: =SUMIFS(Data!E2:E11,Data!C2:C11,"IT",Data!D2:D11,"Pune") | G7: =SUMIFS(Data!E2:E11,Data!C2:C11,"IT",Data!D2:D11,"Pune") -> 58000
A8: 5 | B8: Math & Trig | C8: SUMPRODUCT | D8: Multiplies corresponding values of arrays and returns the sum of those products. | E8: SUMPRODUCT(array1, [array2], ...) | F8: =SUMPRODUCT(Data!E2:E11,Data!H2:H11) | G8: =SUMPRODUCT(Data!E2:E11,Data!H2:H11) -> 1904000
A9: 6 | B9: Math & Trig | C9: ROUND | D9: Rounds a number to a given number of digits. | E9: ROUND(number, num_digits) | F9: =ROUND(3.14159,2) | G9: =ROUND(3.14159,2) -> 3.14
A10: 7 | B10: Math & Trig | C10: ROUNDUP | D10: Always rounds a number UP (away from zero). | E10: ROUNDUP(number, num_digits) | F10: =ROUNDUP(3.141,1) | G10: =ROUNDUP(3.141,1) -> 3.2
A11: 8 | B11: Math & Trig | C11: ROUNDDOWN | D11: Always rounds a number DOWN (towards zero). | E11: ROUNDDOWN(number, num_digits) | F11: =ROUNDDOWN(3.189,1) | G11: =ROUNDDOWN(3.189,1) -> 3.1
A12: 9 | B12: Math & Trig | C12: INT | D12: Rounds a number down to the nearest integer. | E12: INT(number) | F12: =INT(8.9) | G12: =INT(8.9) -> 8
A13: 10 | B13: Math & Trig | C13: ABS | D13: Returns the absolute (positive) value of a number. | E13: ABS(number) | F13: =ABS(-250) | G13: =ABS(-250) -> 250
A14: 11 | B14: Math & Trig | C14: POWER | D14: Returns a number raised to a power. | E14: POWER(number, power) | F14: =POWER(2,5) | G14: =POWER(2,5) -> 32
A15: 12 | B15: Math & Trig | C15: SQRT | D15: Returns the square root of a number. | E15: SQRT(number) | F15: =SQRT(144) | G15: =SQRT(144) -> 12
A16: 13 | B16: Math & Trig | C16: MOD | D16: Returns the remainder after division. | E16: MOD(number, divisor) | F16: =MOD(17,5) | G16: =MOD(17,5) -> 2
A17: 14 | B17: Statistical | C17: AVERAGE | D17: Returns the arithmetic mean of numbers. | E17: AVERAGE(number1, [number2], ...) | F17: =AVERAGE(Data!E2:E11) | G17: =AVERAGE(Data!E2:E11) -> 49000
A18: 15 | B18: Statistical | C18: AVERAGEIF | D18: Average of cells that meet a condition. | E18: AVERAGEIF(range, criteria, [average_range]) | F18: =AVERAGEIF(Data!C2:C11,"IT",Data!E2:E11) | G18: =AVERAGEIF(Data!C2:C11,"IT",Data!E2:E11) -> 61666.667
A19: 16 | B19: Statistical | C19: MIN | D19: Returns the smallest number in a range. | E19: MIN(number1, [number2], ...) | F19: =MIN(Data!E2:E11) | G19: =MIN(Data!E2:E11) -> 38000
A20: 17 | B20: Statistical | C20: MAX | D20: Returns the largest number in a range. | E20: MAX(number1, [number2], ...) | F20: =MAX(Data!E2:E11) | G20: =MAX(Data!E2:E11) -> 65000
A21: 18 | B21: Statistical | C21: COUNT | D21: Counts cells that contain NUMBERS. | E21: COUNT(value1, [value2], ...) | F21: =COUNT(Data!E2:E11) | G21: =COUNT(Data!E2:E11) -> 10
A22: 19 | B22: Statistical | C22: COUNTA | D22: Counts cells that are NOT EMPTY (numbers + text). | E22: COUNTA(value1, [value2], ...) | F22: =COUNTA(Data!B2:B11) | G22: =COUNTA(Data!B2:B11) -> 10
A23: 20 | B23: Statistical | C23: COUNTBLANK | D23: Counts EMPTY cells in a range. | E23: COUNTBLANK(range) | F23: =COUNTBLANK(Data!A2:H12) | G23: =COUNTBLANK(Data!A2:H12) -> 8
A24: 21 | B24: Statistical | C24: COUNTIF | D24: Counts cells that meet ONE condition. | E24: COUNTIF(range, criteria) | F24: =COUNTIF(Data!D2:D11,"Mumbai") | G24: =COUNTIF(Data!D2:D11,"Mumbai") -> 3
A25: 22 | B25: Statistical | C25: COUNTIFS | D25: Counts cells that meet MULTIPLE conditions. | E25: COUNTIFS(range1, criteria1, range2, criteria2, ...) | F25: =COUNTIFS(Data!C2:C11,"Sales",Data!E2:E11,">40000") | G25: =COUNTIFS(Data!C2:C11,"Sales",Data!E2:E11,">40000") -> 3
A26: 23 | B26: Statistical | C26: MEDIAN | D26: Returns the middle value of a set of numbers. | E26: MEDIAN(number1, [number2], ...) | F26: =MEDIAN(Data!E2:E11) | G26: =MEDIAN(Data!E2:E11) -> 46000
A27: 24 | B27: Statistical | C27: MODE | D27: Returns the most frequently occurring value. | E27: MODE(number1, [number2], ...) | F27: =MODE(Data!H2:H11) | G27: =MODE(Data!H2:H11) -> 4
A28: 25 | B28: Statistical | C28: LARGE | D28: Returns the k-th largest value (e.g. 2nd highest). | E28: LARGE(array, k) | F28: =LARGE(Data!E2:E11,2) | G28: =LARGE(Data!E2:E11,2) -> 62000
A29: 26 | B29: Statistical | C29: SMALL | D29: Returns the k-th smallest value. | E29: SMALL(array, k) | F29: =SMALL(Data!E2:E11,2) | G29: =SMALL(Data!E2:E11,2) -> 39000
A30: 27 | B30: Statistical | C30: RANK | D30: Returns the rank of a number within a list. | E30: RANK(number, ref, [order]) | F30: =RANK(Data!E4,Data!E2:E11,0) | G30: =RANK(Data!E4,Data!E2:E11,0) -> 2
A31: 28 | B31: Logical | C31: IF | D31: Checks a condition and returns one value if TRUE and another if FALSE. | E31: IF(logical_test, value_if_true, value_if_false) | F31: =IF(Data!E2>40000,"High Salary","Low Salary") | G31: =IF(Data!E2>40000,"High Salary","Low Salary") -> High Salary
A32: 29 | B32: Logical | C32: Nested IF | D32: An IF inside another IF to test more than two outcomes. | E32: IF(test1, val1, IF(test2, val2, val3)) | F32: =IF(Data!H2>=5,"Excellent",IF(Data!H2>=3,"Good","Poor")) | G32: =IF(Data!H2>=5,"Excellent",IF(Data!H2>=3,"Good","Poor")) -> Good
A33: 30 | B33: Logical | C33: IFS | D33: Tests multiple conditions without nesting (Excel 2019+). | E33: IFS(test1, value1, test2, value2, ...) | F33: =_xlfn.IFS(Data!H3>=5,"Excellent",Data!H3>=3,"Good",TRUE,"Poor") | G33: =_xlfn.IFS(Data!H3>=5,"Excellent",Data!H3>=3,"Good",TRUE(),"Poor") -> Excellent
A34: 31 | B34: Logical | C34: AND | D34: Returns TRUE only if ALL conditions are TRUE. | E34: AND(logical1, [logical2], ...) | F34: =AND(Data!C2="Sales",Data!E2>40000) | G34: =AND(Data!C2="Sales",Data!E2>40000) -> TRUE
A35: 32 | B35: Logical | C35: OR | D35: Returns TRUE if ANY one condition is TRUE. | E35: OR(logical1, [logical2], ...) | F35: =OR(Data!D3="Mumbai",Data!D3="Pune") | G35: =OR(Data!D3="Mumbai",Data!D3="Pune") -> TRUE
A36: 33 | B36: Logical | C36: NOT | D36: Reverses a logical value (TRUE becomes FALSE). | E36: NOT(logical) | F36: =NOT(Data!C2="HR") | G36: =NOT(Data!C2="HR") -> TRUE
A37: 34 | B37: Logical | C37: IFERROR | D37: Returns a custom value if a formula gives an error. | E37: IFERROR(value, value_if_error) | F37: =IFERROR(Data!E2/Data!G3,"Cannot divide by 0") | G37: =IFERROR(Data!E2/Data!G3,"Cannot divide by 0") -> Cannot divide by 0
A38: 35 | B38: Text | C38: CONCATENATE | D38: Joins two or more text strings into one. | E38: CONCATENATE(text1, [text2], ...) | F38: =CONCATENATE(Data!B3," - ",Data!C3) | G38: =CONCATENATE(Data!B3," - ",Data!C3) -> Priya Patil - HR
A39: 36 | B39: Text | C39: CONCAT | D39: Newer version of CONCATENATE; also accepts ranges. | E39: CONCAT(text1, [text2], ...) | F39: =_xlfn.CONCAT(Data!B4," (",Data!D4,")") | G39: =_xlfn.CONCAT(Data!B4," (",Data!D4,")") -> Amit Joshi (Mumbai)
A40: 37 | B40: Text | C40: TEXTJOIN | D40: Joins text with a delimiter and can ignore blanks. | E40: TEXTJOIN(delimiter, ignore_empty, text1, ...) | F40: =_xlfn.TEXTJOIN(", ",TRUE,Data!D2:D5) | G40: =_xlfn.TEXTJOIN(", ",TRUE(),Data!D2:D5) -> Mumbai, Pune, Mumbai, Thane
A41: 38 | B41: Text | C41: & operator | D41: Ampersand joins text just like CONCATENATE. | E41: text1 & text2 | F41: =Data!B5&" works in "&Data!C5 | G41: =Data!B5&" works in "&Data!C5 -> Sneha Kulkarni works in Sales
...
